Workbook

Sheet RAB
A1: RENCANA ANGGARAN BIAYA — Alat Praktikum Fluida Dinamis (Debit, Kontinuitas, Bernoulli)
A2: Desain: Rev. 08 — satu tangki, pompa langsung, leher angsa, tanpa servo. Paket inti = zona A + B.
A3: Harga perkiraan = kisaran marketplace Indonesia, belum diverifikasi. Kolom kuning diisi setelah riset; total, subtotal, dan ringkasan terhitung otomatis. Total Dipakai memakai harga online bila sudah diisi.
A5: No | B5: Nama Barang | C5: Spesifikasi | D5: Fungsi | E5: Paket | F5: Satuan | G5: Jumlah | H5: Harga Perkiraan (Rp/satuan) | I5: Total Perkiraan (Rp) | J5: Harga Online Shop (Rp/satuan) | K5: Total Online (Rp) | L5: Total Dipakai (Rp) | M5: Selisih (Online − Perkiraan) | N5: Toko / Link | O5: Status | P5: Catatan
A6: A. ELEKTRONIK
A7: 1 | B7: ESP32-C3 Super Mini | C7: RISC-V 160 MHz, WiFi/BLE, USB-C, logika 3,3 V | D7: Otak alat: baca S1, kontrol PI pompa, layar, tombol, log data | E7: Inti | F7: pcs | G7: 2 | H7: 40000 | I7: =G7*H7 | K7: =IF(J7="","",G7*J7) | L7: =IF(J7="",I7,K7) | M7: =IF(J7="","",K7-I7) | O7: Belum | P7: 1 cadangan. Pin tidak tahan 5 V; jangan pakai GPIO 2/8/9 untuk kendali pompa
A8: 2 | B8: LCD 20×4 + modul I2C | C8: 20×4 karakter, backlight | D8: Tampil debit, kecepatan, prediksi, pesan error | E8: Inti | F8: pcs | G8: 1 | H8: 75000 | I8: =G8*H8 | J8: 150000 | K8: =IF(J8="","",G8*J8) | L8: =IF(J8="",I8,K8) | M8: =IF(J8="","",K8-I8) | O8: Belum
A9: 3 | B9: Sensor flow YF-S201 (S1) | C9: Ulir G1/2", 1–30 L/min, hall-effect | D9: Debit utama | E9: Inti | F9: pcs | G9: 1 | H9: 35000 | I9: =G9*H9 | J9: 29189 | K9: =IF(J9="","",G9*J9) | L9: =IF(J9="",I9,K9) | M9: =IF(J9="","",K9-I9) | O9: Diterima | P9: Wajib dikalibrasi volumetrik
A10: 4 | B10: Sensor flow YF-S201 (cadangan) | C10: Sama dengan S1 | D10: Suku cadang bila S1 rusak saat pengambilan data | E10: Inti | F10: pcs | G10: 1 | H10: 35000 | I10: =G10*H10 | K10: =IF(J10="","",G10*J10) | L10: =IF(J10="",I10,K10) | M10: =IF(J10="","",K10-I10) | O10: Belum | P10: Bisa dicoret kalau budget ketat
A11: 5 | B11: Pompa celup DC 12 V | C11: MAXPUMP brushless 12 V, 19 W, 800 L/jam, head maks 5 m, outlet 1/2" | D11: Mendorong aliran | E11: Inti | F11: pcs | G11: 1 | H11: 120000 | I11: =G11*H11 | K11: =IF(J11="","",G11*J11) | L11: =IF(J11="",I11,K11) | M11: =IF(J11="","",K11-I11) | N11: https://shopee.co.id/MAXPUMP-Pompa-Celup-Air-Bersih-DC-12V-24V-Submersible-Pump-Pompa-Kolam-Ikan-Brushless-5m-Aquarium-Hidroponik-i.17799491.12107841427?extraParams=%7B%22display_model_id%22%3A227492409707%2C%22model_selection_logic%22%3A3%7D | O11: Belum | P11: Tanya penjual: tegangan minimum & bisa diatur kecepatannya? Uji ember: 4–6 L/min stabil
A12: 6 | B12: MOSFET gate 3,3 V | C12: AO3400 / IRLML6244 (atau modul + transistor pendorong), ≥ 3 A | D12: Saklar PWM pompa / kendali buck | E12: Inti | F12: pcs | G12: 2 | H12: 7500 | I12: =G12*H12 | K12: =IF(J12="","",G12*J12) | L12: =IF(J12="",I12,K12) | M12: =IF(J12="","",K12-I12) | O12: Belum | P12: Pull-down 10 kΩ di gate → pompa mati saat reset/upload
A13: 7 | B13: Modul buck DC-DC 5 A (pompa) | C13: XL4015 / setara, tegangan keluaran bisa diatur | D13: Atur kecepatan pompa lewat tegangan (pompa brushless tanpa kabel PWM) | E13: Inti | F13: pcs | G13: 1 | H13: 30000 | I13: =G13*H13 | K13: =IF(J13="","",G13*J13) | L13: =IF(J13="",I13,K13) | M13: =IF(J13="","",K13-I13) | O13: Belum | P13: Cara kendali dari MCU ditentukan saat uji bangku
A14: 8 | B14: Level shifter 4 kanal | C14: BSS138, 3,3 V ↔ 5 V | D14: Sinyal YF-S201 & I2C LCD ke ESP32-C3 | E14: Inti | F14: pcs | G14: 1 | H14: 8000 | I14: =G14*H14 | K14: =IF(J14="","",G14*J14) | L14: =IF(J14="",I14,K14) | M14: =IF(J14="","",K14-I14) | O14: Belum
A15: 9 | B15: Modul step-down 12 V → 5 V | C15: LM2596 / Mini-360 | D15: Catu daya MCU & LCD | E15: Inti | F15: pcs | G15: 1 | H15: 12000 | I15: =G15*H15 | J15: 0 | K15: =IF(J15="","",G15*J15) | L15: =IF(J15="",I15,K15) | M15: =IF(J15="","",K15-I15) | O15: Belum
A16: 10 | B16: Adaptor 12 V 5 A | C16: Switching, casing tertutup | D16: Sumber daya utama | E16: Inti | F16: pcs | G16: 1 | H16: 70000 | I16: =G16*H16 | J16: 0 | K16: =IF(J16="","",G16*J16) | L16: =IF(J16="",I16,K16) | M16: =IF(J16="","",K16-I16) | O16: Belum | P16: Letakkan jauh dari air
A17: 11 | B17: Sekring + holder inline | C17: 3–5 A | D17: Proteksi hubung singkat | E17: Inti | F17: set | G17: 1 | H17: 8000 | I17: =G17*H17 | K17: =IF(J17="","",G17*J17) | L17: =IF(J17="",I17,K17) | M17: =IF(J17="","",K17-I17) | O17: Belum
A18: 12 | B18: Saklar daya (rocker) | C18: 6 A | D18: ON/OFF alat | E18: Inti | F18: pcs | G18: 1 | H18: 5000 | I18: =G18*H18 | K18: =IF(J18="","",G18*J18) | L18: =IF(J18="",I18,K18) | M18: =IF(J18="","",K18-I18) | O18: Belum
A19: 13 | B19: Jack DC panel female | C19: 5,5 × 2,1 mm | D19: Input adaptor | E19: Inti | F19: pcs | G19: 1 | H19: 5000 | I19: =G19*H19 | K19: =IF(J19="","",G19*J19) | L19: =IF(J19="",I19,K19) | M19: =IF(J19="","",K19-I19) | O19: Belum
A20: 14 | B20: Potensiometer 10 kΩ + knob | C20: Linear, dudukan panel | D20: Kenop target debit | E20: Inti | F20: pcs | G20: 1 | H20: 10000 | I20: =G20*H20 | K20: =IF(J20="","",G20*J20) | L20: =IF(J20="",I20,K20) | M20: =IF(J20="","",K20-I20) | O20: Belum
A21: 15 | B21: Tombol tekan panel | C21: 12 mm, momentary | D21: Tombol CEK + Start/Stop | E21: Inti | F21: pcs | G21: 2 | H21: 5000 | I21: =G21*H21 | K21: =IF(J21="","",G21*J21) | L21: =IF(J21="",I21,K21) | M21: =IF(J21="","",K21-I21) | O21: Belum
A22: 16 | B22: Buzzer aktif 5 V | D22: Sonifikasi debit & alarm | E22: Inti | F22: pcs | G22: 1 | H22: 5000 | I22: =G22*H22 | K22: =IF(J22="","",G22*J22) | L22: =IF(J22="",I22,K22) | M22: =IF(J22="","",K22-I22) | O22: Belum
A23: 17 | B23: Komponen pasif | C23: Resistor 10 kΩ & 4,7 kΩ, kapasitor filter, dioda flyback 1N5819 | D23: Pull-down gate, pull-up & filter sensor, proteksi pompa | E23: Inti | F23: paket | G23: 1 | H23: 15000 | I23: =G23*H23 | J23: 0 | K23: =IF(J23="","",G23*J23) | L23: =IF(J23="",I23,K23) | M23: =IF(J23="","",K23-I23) | O23: Belum
A24: 18 | B24: PCB lubang + header + terminal sekrup | C24: ± 7 × 9 cm | D24: Papan rangkaian | E24: Inti | F24: set | G24: 1 | H24: 20000 | I24: =G24*H24 | K24: =IF(J24="","",G24*J24) | L24: =IF(J24="",I24,K24) | M24: =IF(J24="","",K24-I24) | O24: Belum
A25: 19 | B25: Kabel & heatshrink | C25: Kabel serabut, jumper, kabel sensor berpelindung ± 5 m | D25: Pengkabelan; jalur sensor dipisah dari kabel pompa | E25: Inti | F25: paket | G25: 1 | H25: 35000 | I25: =G25*H25 | K25: =IF(J25="","",G25*J25) | L25: =IF(J25="",I25,K25) | M25: =IF(J25="","",K25-I25) | O25: Belum | P25: Kabel berpelindung mengurangi pulsa palsu dari derau motor
A26: 20 | B26: Kotak elektronik tahan cipratan | C26: Junction box IP65 ± 15 × 10 × 7 cm | D26: Elektronik di atas garis air | E26: Inti | F26: pcs | G26: 1 | H26: 45000 | I26: =G26*H26 | K26: =IF(J26="","",G26*J26) | L26: =IF(J26="",I26,K26) | M26: =IF(J26="","",K26-I26) | O26: Belum
A27: 21 | B27: Sensor flow YF-S401 (S2) | C27: 0,3–6 L/min | D27: Sensor kedua di zona C | E27: Lengkap | F27: pcs | G27: 1 | H27: 45000 | I27: =G27*H27 | J27: 42211 | K27: =IF(J27="","",G27*J27) | L27: =IF(J27="",I27,K27) | M27: =IF(J27="","",K27-I27) | O27: Diterima | P27: Uji rugi tekanan dulu: harus ≤ ± 90 mm di 6 L/min
A28: 22 | B28: Stop kontak / adaptor ber-RCD | C28: Portable RCD 30 mA | D28: Keselamatan listrik dekat air | E28: Opsional | F28: pcs | G28: 1 | H28: 200000 | I28: =G28*H28 | K28: =IF(J28="","",G28*J28) | L28: =IF(J28="",I28,K28) | M28: =IF(J28="","",K28-I28) | O28: Belum | P28: Tidak perlu jika stop kontak lab sudah ber-RCD
A29: 23 | B29: Sensor tekanan analog 0–10 kPa | C29: MPX5010DP / XGZP6847 | D29: Demo hidrostatis tangki | E29: Opsional | F29: pcs | G29: 1 | H29: 120000 | I29: =G29*H29 | K29: =IF(J29="","",G29*J29) | L29: =IF(J29="",I29,K29) | M29: =IF(J29="","",K29-I29) | O29: Belum | P29: Hanya jika hidrostatis masuk materi skripsi
A30: 24 | B30: Sensor ultrasonik HC-SR04 | D30: Tinggi air tangki (demo hidrostatis) | E30: Opsional | F30: pcs | G30: 1 | H30: 15000 | I30: =G30*H30 | K30: =IF(J30="","",G30*J30) | L30: =IF(J30="",I30,K30) | M30: =IF(J30="","",K30-I30) | O30: Belum | P30: Pasangan sensor tekanan di atas
B31: Subtotal Elektronik — paket inti | I31: =SUMIFS(I7:I30,E7:E30,"Inti") | K31: =SUMIFS(K7:K30,E7:E30,"Inti") | L31: =SUMIFS(L7:L30,E7:E30,"Inti")
A33: B. MEKANIS — HIDROLIK (pipa, aliran, manometer)
A34: 25 | B34: Tangki akrilik custom + tutup | C34: ± 30 × 20 × 25 cm, tebal 4–5 mm | D34: Tangki air tunggal | E34: Inti | F34: pcs | G34: 1 | H34: 220000 | I34: =G34*H34 | K34: =IF(J34="","",G34*J34) | L34: =IF(J34="",I34,K34) | M34: =IF(J34="","",K34-I34) | O34: Belum | P34: Alternatif hemat: kontainer plastik bening ± Rp60 rb. Uji bangku pakai ember
A35: 26 | B35: Sekat tangki | C35: Potongan akrilik | D35: Pisahkan air balik dari hisapan pompa | E35: Inti | F35: pcs | G35: 1 | H35: 15000 | I35: =G35*H35 | K35: =IF(J35="","",G35*J35) | L35: =IF(J35="",I35,K35) | M35: =IF(J35="","",K35-I35) | O35: Belum
A36: 27 | B36: Saringan hisapan pompa | C36: Spons / kasa halus | D36: Cegah serpihan menyumbat S1 & sadap | E36: Inti | F36: pcs | G36: 1 | H36: 10000 | I36: =G36*H36 | K36: =IF(J36="","",G36*J36) | L36: =IF(J36="",I36,K36) | M36: =IF(J36="","",K36-I36) | O36: Belum
A37: 28 | B37: Tabung akrilik OD 25 / ID 19 mm | C37: Panjang 1 m per batang | D37: Pipa uji: sebelum venturi & tanjakan | E37: Inti | F37: batang | G37: 2 | H37: 75000 | I37: =G37*H37 | K37: =IF(J37="","",G37*J37) | L37: =IF(J37="",I37,K37) | M37: =IF(J37="","",K37-I37) | O37: Belum | P37: Ukur ID riil dengan jangka sorong sebelum cetak venturi
A38: 29 | B38: Venturi cetak 3D PETG | C38: ID 19 → leher 10 → 19, nipple sadap menyatu | D38: Zona A (bukti utama) | E38: Inti | F38: pcs | G38: 3 | H38: 50000 | I38: =G38*H38 | K38: =IF(J38="","",G38*J38) | L38: =IF(J38="",I38,K38) | M38: =IF(J38="","",K38-I38) | O38: Belum | P38: Cetak 3, pakai yang lehernya paling presisi (Δh ∝ d⁻⁴)
A39: 30 | B39: Katup searah swing/flapper 3/4" | C39: Tekanan buka rendah (bukan tipe pegas) | D39: Tahan air saat pompa mati → uji nol | E39: Inti | F39: pcs | G39: 1 | H39: 50000 | I39: =G39*H39 | K39: =IF(J39="","",G39*J39) | L39: =IF(J39="",I39,K39) | M39: =IF(J39="","",K39-I39) | O39: Belum | P39: Uji bangku: tahan kolom 170 mm ≥ 10 menit
A40: 31 | B40: Ball valve PVC 3/4" | D40: Penyetelan & perawatan (bukan kenop siswa) | E40: Inti | F40: pcs | G40: 1 | H40: 15000 | I40: =G40*H40 | K40: =IF(J40="","",G40*J40) | L40: =IF(J40="",I40,K40) | M40: =IF(J40="","",K40-I40) | O40: Belum
A41: 32 | B41: Pipa PVC 3/4" AW | C41: 1 batang 4 m | D41: Leher angsa, pipa balik, pipa limpah | E41: Inti | F41: batang | G41: 1 | H41: 45000 | I41: =G41*H41 | K41: =IF(J41="","",G41*J41) | L41: =IF(J41="",I41,K41) | M41: =IF(J41="","",K41-I41) | O41: Belum
A42: 33 | B42: Fitting PVC 3/4" | C42: Elbow, tee, sok drat (± 10 pcs) | D42: Sambungan pipa | E42: Inti | F42: paket | G42: 1 | H42: 50000 | I42: =G42*H42 | K42: =IF(J42="","",G42*J42) | L42: =IF(J42="",I42,K42) | M42: =IF(J42="","",K42-I42) | O42: Belum
...

Sheet Keuangan
A1: KEUANGAN PROYEK — dana masuk, pengeluaran, sisa
A2: Sel kuning diisi. Simpan foto nota di folder anggaran/nota/ lalu tulis nama filenya di kolom File nota; kolom Link otomatis membukanya.
A3: Buka folder nota
A5: RINGKASAN
A6: Dana diterima | D6: =D18
A7: Sudah dipakai | D7: =E62
A8: Sisa dana | D8: =D6-D7 | E8: =IF(D8<0,"Dana kurang — minta tambahan","")
A10: 1. DANA MASUK
A11: Tanggal | B11: Keterangan | D11: Jumlah | G11: File nota / bukti | H11: Link | I11: Catatan
B12: DP dari client | D12: 1000000 | H12: =IF(G12="","",HYPERLINK("nota/"&G12,"buka")) | I12: Isi tanggal transfer
H13: =IF(G13="","",HYPERLINK("nota/"&G13,"buka"))
H14: =IF(G14="","",HYPERLINK("nota/"&G14,"buka"))
H15: =IF(G15="","",HYPERLINK("nota/"&G15,"buka"))
H16: =IF(G16="","",HYPERLINK("nota/"&G16,"buka"))
H17: =IF(G17="","",HYPERLINK("nota/"&G17,"buka"))
B18: Total dana masuk | D18: =SUM(D12:D17)
A20: 2. PENGELUARAN
A21: Tanggal | B21: Barang / keperluan | C21: Jumlah | D21: Harga satuan | E21: Total | F21: Toko | G21: File nota | H21: Link | I21: Catatan
B22: Sensor flow YF-S401 (S2) | C22: 1 | D22: 42211 | E22: =IF(D22="","",IF(C22="",1,C22)*D22) | H22: =IF(G22="","",HYPERLINK("nota/"&G22,"buka")) | I22: Untuk uji rugi tekanan zona C
B23: Sensor flow YF-S201 (S1) | C23: 1 | D23: 29189 | E23: =IF(D23="","",IF(C23="",1,C23)*D23) | H23: =IF(G23="","",HYPERLINK("nota/"&G23,"buka"))
E24: =IF(D24="","",IF(C24="",1,C24)*D24) | H24: =IF(G24="","",HYPERLINK("nota/"&G24,"buka"))
E25: =IF(D25="","",IF(C25="",1,C25)*D25) | H25: =IF(G25="","",HYPERLINK("nota/"&G25,"buka"))
E26: =IF(D26="","",IF(C26="",1,C26)*D26) | H26: =IF(G26="","",HYPERLINK("nota/"&G26,"buka"))
E27: =IF(D27="","",IF(C27="",1,C27)*D27) | H27: =IF(G27="","",HYPERLINK("nota/"&G27,"buka"))
E28: =IF(D28="","",IF(C28="",1,C28)*D28) | H28: =IF(G28="","",HYPERLINK("nota/"&G28,"buka"))
E29: =IF(D29="","",IF(C29="",1,C29)*D29) | H29: =IF(G29="","",HYPERLINK("nota/"&G29,"buka"))
E30: =IF(D30="","",IF(C30="",1,C30)*D30) | H30: =IF(G30="","",HYPERLINK("nota/"&G30,"buka"))
E31: =IF(D31="","",IF(C31="",1,C31)*D31) | H31: =IF(G31="","",HYPERLINK("nota/"&G31,"buka"))
E32: =IF(D32="","",IF(C32="",1,C32)*D32) | H32: =IF(G32="","",HYPERLINK("nota/"&G32,"buka"))
E33: =IF(D33="","",IF(C33="",1,C33)*D33) | H33: =IF(G33="","",HYPERLINK("nota/"&G33,"buka"))
E34: =IF(D34="","",IF(C34="",1,C34)*D34) | H34: =IF(G34="","",HYPERLINK("nota/"&G34,"buka"))
E35: =IF(D35="","",IF(C35="",1,C35)*D35) | H35: =IF(G35="","",HYPERLINK("nota/"&G35,"buka"))
... E61: =IF(D61="","",IF(C61="",1,C61)*D61) | H61: =IF(G61="","",HYPERLINK("nota/"&G61,"buka"))
B62: Total pengeluaran | E62: =SUM(E22:E61)

Sheet Ringkasan
A1: RINGKASAN RAB — Rev. 08
A2: Semua angka dihitung dari sheet RAB. Sel kuning boleh diubah.
A4: Target budget total (komponen + jasa) | B4: 2000000
A5: Kontingensi (cadangan harga naik / salah beli) | B5: 0.1
A7: 1. PAKET INTI (zona A + B)
A8: Pos | B8: Perkiraan | C8: Online (yang sudah diisi) | D8: Dipakai | E8: Harga online terisi
A9: Elektronik | B9: =SUMIFS(RAB!$I$7:$I$30,RAB!$E$7:$E$30,"Inti") | C9: =SUMIFS(RAB!$K$7:$K$30,RAB!$E$7:$E$30,"Inti") | D9: =SUMIFS(RAB!$L$7:$L$30,RAB!$E$7:$E$30,"Inti") | E9: =COUNTIFS(RAB!$E$7:$E$30,"Inti",RAB!$J$7:$J$30,"<>")&" / "&COUNTIFS(RAB!$E$7:$E$30,"Inti")
A10: Mekanis — Hidrolik | B10: =SUMIFS(RAB!$I$34:$I$57,RAB!$E$34:$E$57,"Inti") | C10: =SUMIFS(RAB!$K$34:$K$57,RAB!$E$34:$E$57,"Inti") | D10: =SUMIFS(RAB!$L$34:$L$57,RAB!$E$34:$E$57,"Inti") | E10: =COUNTIFS(RAB!$E$34:$E$57,"Inti",RAB!$J$34:$J$57,"<>")&" / "&COUNTIFS(RAB!$E$34:$E$57,"Inti")
A11: Mekanis — Struktur & Panel | B11: =SUMIFS(RAB!$I$61:$I$68,RAB!$E$61:$E$68,"Inti") | C11: =SUMIFS(RAB!$K$61:$K$68,RAB!$E$61:$E$68,"Inti") | D11: =SUMIFS(RAB!$L$61:$L$68,RAB!$E$61:$E$68,"Inti") | E11: =COUNTIFS(RAB!$E$61:$E$68,"Inti",RAB!$J$61:$J$68,"<>")&" / "&COUNTIFS(RAB!$E$61:$E$68,"Inti")
A12: Bahan Habis Pakai | B12: =SUMIFS(RAB!$I$72:$I$77,RAB!$E$72:$E$77,"Inti") | C12: =SUMIFS(RAB!$K$72:$K$77,RAB!$E$72:$E$77,"Inti") | D12: =SUMIFS(RAB!$L$72:$L$77,RAB!$E$72:$E$77,"Inti") | E12: =COUNTIFS(RAB!$E$72:$E$77,"Inti",RAB!$J$72:$J$77,"<>")&" / "&COUNTIFS(RAB!$E$72:$E$77,"Inti")
A13: Alat Bantu & Kalibrasi | B13: =SUMIFS(RAB!$I$81:$I$85,RAB!$E$81:$E$85,"Inti") | C13: =SUMIFS(RAB!$K$81:$K$85,RAB!$E$81:$E$85,"Inti") | D13: =SUMIFS(RAB!$L$81:$L$85,RAB!$E$81:$E$85,"Inti") | E13: =COUNTIFS(RAB!$E$81:$E$85,"Inti",RAB!$J$81:$J$85,"<>")&" / "&COUNTIFS(RAB!$E$81:$E$85,"Inti")
A14: Subtotal komponen | B14: =SUM(B9:B13) | C14: =SUM(C9:C13) | D14: =SUM(D9:D13)
A15: Kontingensi | B15: =B14*$B$5 | D15: =D14*$B$5 | E15: Subtotal komponen × persentase di B5
A16: Biaya lain (ongkir, transport) | B16: =SUMIFS(RAB!$I$89:$I$90,RAB!$E$89:$E$90,"Inti") | C16: =SUMIFS(RAB!$K$89:$K$90,RAB!$E$89:$E$90,"Inti") | D16: =SUMIFS(RAB!$L$89:$L$90,RAB!$E$89:$E$90,"Inti")
A17: Total biaya barang | B17: =B14+B15+B16 | D17: =D14+D15+D16
A18: Jasa | B18: =SUMIFS(RAB!$I$94:$I$100,RAB!$E$94:$E$100,"Inti") | D18: =SUMIFS(RAB!$L$94:$L$100,RAB!$E$94:$E$100,"Inti")
A19: TOTAL PAKET INTI | B19: =B17+B18 | D19: =D17+D18
A20: Selisih terhadap target (+ = melebihi) | B20: =B19-$B$4 | D20: =D19-$B$4
A21: Status | B21: =IF(B19<=$B$4,"Masuk target","Melebihi target") | D21: =IF(D19<=$B$4,"Masuk target","Melebihi target")
A22: Porsi jasa dari total | B22: =B18/B19 | D22: =D18/D19
A24: 2. PAKET LENGKAP & OPSIONAL
A25: Pos | B25: Perkiraan | C25: Online (yang sudah diisi) | D25: Dipakai | E25: Keterangan
A26: Tambahan paket lengkap (zona C + S2) | B26: =SUMIFS(RAB!$I$6:$I$102,RAB!$E$6:$E$102,"Lengkap")+(SUMIFS(RAB!$I$6:$I$102,RAB!$E$6:$E$102,"Lengkap")-SUMIFS(RAB!$I$94:$I$100,RAB!$E$94:$E$100,"Lengkap"))*$B$5 | C26: =SUMIFS(RAB!$K$6:$K$102,RAB!$E$6:$E$102,"Lengkap") | D26: =SUMIFS(RAB!$L$6:$L$102,RAB!$E$6:$E$102,"Lengkap")+(SUMIFS(RAB!$L$6:$L$102,RAB!$E$6:$E$102,"Lengkap")-SUMIFS(RAB!$L$94:$L$100,RAB!$E$94:$E$100,"Lengkap"))*$B$5 | E26: Barang + jasa tambahan, kontingensi hanya untuk barang
A27: TOTAL PAKET LENGKAP | B27: =B19+B26 | D27: =D19+D26 | E27: Syarat: YF-S401 lolos uji rugi tekanan
A28: Item opsional (tidak masuk total) | B28: =SUMIFS(RAB!$I$6:$I$102,RAB!$E$6:$E$102,"Opsional") | C28: =SUMIFS(RAB!$K$6:$K$102,RAB!$E$6:$E$102,"Opsional") | D28: =SUMIFS(RAB!$L$6:$L$102,RAB!$E$6:$E$102,"Opsional") | E28: RCD, demo hidrostatis, tabung pitot — ditambahkan terpisah bila dipilih

Sheet Petunjuk
A1: CARA MEMAKAI RAB
A2: 1. Isi kolom kuning di sheet RAB setelah riset: Harga Online Shop (per satuan), Toko / Link, dan Status.
A3: 2. Total Online, Total Dipakai, Selisih, subtotal, dan sheet Ringkasan terhitung otomatis.
A4: 3. Total Dipakai = harga online jika sudah diisi, jika belum memakai harga perkiraan. Ringkasan memakai angka ini.
A5: 4. Barang yang sudah dimiliki (mis. jangka sorong): ubah Jumlah jadi 0, jangan hapus barisnya.
A6: 5. Kolom Paket: Inti = masuk total paket inti; Lengkap = hanya paket lengkap; Opsional = tidak masuk total.
A7: 6. Target budget dan persentase kontingensi bisa diubah di sheet Ringkasan (sel kuning B4 dan B5).
A8: 7. Menambah barang: sisipkan baris di dalam kelompoknya (di atas baris Subtotal) lalu salin rumus kolom I, K, L, M dari baris di atasnya.
A10: CATATAN
A11: • Harga perkiraan adalah kisaran marketplace, bukan harga pasti. Verifikasi sebelum dikirim ke client.
A12: • Jangan belanja penuh sebelum kesepakatan tertulis dan DP.
A13: • Ukuran pipa (ID 19 / 10 / 13 mm) masih asumsi tabung akrilik tebal 3 mm; ukur ID riil sebelum mencetak venturi.
... A20: • Setelah membeli, isi juga harga beli dan status 'Diterima' di sheet RAB supaya total RAB memakai harga nyata.
